<?xml version="1.0" encoding="UTF-8"?>
<!-- Generated by org.testng.reporters.JUnitReportReporter -->
<testsuite hostname="nova-PC" name="com.webirrse.code.demo.TestListener" tests="4" failures="1" timestamp="16 Jun 2017 04:48:15 GMT" time="0.019" errors="2">
  <testcase name="testAssert4" time="0.002" classname="com.webirrse.code.demo.TestListener">
    <error type="java.lang.Throwable">
      <![CDATA[java.lang.Throwable
	at message : 比较两个数是否相等： expected [3] but found [4] in method : .testAssert4(TestListener:19)
	at com.webirrse.code.demo.TestListener.testAssert4(TestListener.java:19)
]]>
    </error>
  </testcase> <!-- testAssert4 -->
  <testcase name="testAssert5" time="0.001" classname="com.webirrse.code.demo.TestListener"/>
  <testcase name="testAssert3" time="0.014" classname="com.webirrse.code.demo.TestListener">
    <error type="java.lang.Throwable">
      <![CDATA[java.lang.Throwable
	at message : 比较两个数是否相等： expected [3] but found [2] in method : .testAssert3(TestListener:13)
	at com.webirrse.code.demo.TestListener.testAssert3(TestListener.java:13)
	at message : 比较两个数是否相等： expected [2] but found [1] in method : .testAssert3(TestListener:14)
	at com.webirrse.code.demo.TestListener.testAssert3(TestListener.java:14)
]]>
    </error>
  </testcase> <!-- testAssert3 -->
  <testcase name="testAssert6" time="0.002" classname="com.webirrse.code.demo.TestListener">
    <failure type="java.lang.AssertionError" message="11比较两个数是否相等： expected [5] but found [4]">
      <![CDATA[java.lang.AssertionError: 11比较两个数是否相等： expected [5] but found [4]
	at org.testng.Assert.fail(Assert.java:94)
	at org.testng.Assert.failNotEquals(Assert.java:496)
	at org.testng.Assert.assertEquals(Assert.java:125)
	at org.testng.Assert.assertEquals(Assert.java:372)
	at com.webirrse.code.demo.TestListener.testAssert6(TestListener.java:32)
	at sun.reflect.NativeMethodAccessorImpl.invoke0(Native Method)
	at sun.reflect.NativeMethodAccessorImpl.invoke(Unknown Source)
	at sun.reflect.DelegatingMethodAccessorImpl.invoke(Unknown Source)
	at java.lang.reflect.Method.invoke(Unknown Source)
	at org.testng.internal.MethodInvocationHelper.invokeMethod(MethodInvocationHelper.java:85)
	at org.testng.internal.Invoker.invokeMethod(Invoker.java:639)
	at org.testng.internal.Invoker.invokeTestMethod(Invoker.java:816)
	at org.testng.internal.Invoker.invokeTestMethods(Invoker.java:1124)
	at org.testng.internal.TestMethodWorker.invokeTestMethods(TestMethodWorker.java:125)
	at org.testng.internal.TestMethodWorker.run(TestMethodWorker.java:108)
	at org.testng.TestRunner.privateRun(TestRunner.java:774)
	at org.testng.TestRunner.run(TestRunner.java:624)
	at org.testng.SuiteRunner.runTest(SuiteRunner.java:359)
	at org.testng.SuiteRunner.runSequentially(SuiteRunner.java:354)
	at org.testng.SuiteRunner.privateRun(SuiteRunner.java:312)
	at org.testng.SuiteRunner.run(SuiteRunner.java:261)
	at org.testng.SuiteRunnerWorker.runSuite(SuiteRunnerWorker.java:52)
	at org.testng.SuiteRunnerWorker.run(SuiteRunnerWorker.java:86)
	at org.testng.TestNG.runSuitesSequentially(TestNG.java:1215)
	at org.testng.TestNG.runSuitesLocally(TestNG.java:1140)
	at org.testng.TestNG.run(TestNG.java:1048)
	at org.testng.remote.AbstractRemoteTestNG.run(AbstractRemoteTestNG.java:132)
	at org.testng.remote.RemoteTestNG.initAndRun(RemoteTestNG.java:230)
	at org.testng.remote.RemoteTestNG.main(RemoteTestNG.java:76)
]]>
    </failure>
  </testcase> <!-- testAssert6 -->
</testsuite> <!-- com.webirrse.code.demo.TestListener -->
